<?xml version='1.0' encoding='utf-8'?>
<robot name="SG_finger_planar">
  <link name="base_link">
    <visual>
      <origin xyz="0 0 0.1" rpy="0 0 0" />
      <geometry>
        <box size="0.64 1.0 0.2" />
      </geometry>
      <material name="purple1">
        <color rgba="0.1 0.8 0.1 1.0" />
      </material>
    </visual>
    <collision>
      <origin xyz="0 0 0.1" rpy="0 0 0" />
      <geometry>
        <box size="0.64 1.0 0.2" />
      </geometry>
    </collision>
    <inertial>
      <mass value="0.6" />
      <inertia ixx="1" ixy="0" ixz="0" iyy="1" iyz="0" izz="1" />
    </inertial>
  </link>
  <link name="act0Seg0">
    <visual>
      <origin xyz="0 0 0.025" rpy="0 0 0" />
      <geometry>
        <box size="0.46 0.34 0.05" />
      </geometry>
      <material name="darkpurple">
        <color rgba="0.42 0.33 0.63 1.0" />
      </material>
    </visual>
    <collision>
      <origin xyz="0 0 0.025" rpy="0 0 0" />
      <geometry>
        <box size="0.46 0.34 0.05" />
      </geometry>
    </collision>
    <inertial>
      <mass value="0.0015" />
      <inertia ixx="0.0152488" ixy="0" ixz="0" iyy="0.0152488" iyz="0" izz="0.0152488" />
    </inertial>
  </link>
  <joint name="base_link_to_act0Seg0" type="fixed">
    <parent link="base_link" />
    <child link="act0Seg0" />
    <origin xyz="0 0 0.2" rpy="0 0 0" />
    <axis xyz="1 0 0" />
  </joint>
  <link name="act0Seg1">
    <visual>
      <origin xyz="0.0 0.0 0.05" rpy="0.0 0.0 0.0" />
      <geometry>
        <box size="0.46 0.34 0.1" />
      </geometry>
      <material name="darkpurple">
        <color rgba="0.42 0.33 0.63 1.0" />
      </material>
    </visual>
    <collision>
      <origin xyz="0.0 0.0 0.05" rpy="0.0 0.0 0.0" />
      <geometry>
        <box size="0.46 0.34 0.1" />
      </geometry>
    </collision>
    <inertial>
      <mass value="0.0015" />
      <inertia ixx="0.0152488" ixy="0" ixz="0" iyy="0.0152488" iyz="0" izz="0.0152488" />
    </inertial>
  </link>
  <joint name="act0Seg0_to_act0Seg1_ax0" type="revolute">
    <parent link="act0Seg0" />
    <child link="act0Seg1" />
    <origin xyz="0.0 0.0 0.05" rpy="0.0 0.0 0.0" />
    <axis xyz="1 0 0" />
    <limit lower="-3.141592" upper="3.141592" effort="100" velocity="3" />
  </joint>
  <link name="act0Seg1helper_shape">
    <visual>
      <origin xyz="0 0 0.0" rpy="0 -1.5707963267948966 0" />
      <geometry>
        <cylinder length="0.46" radius="0.17" />
      </geometry>
      <material name="darkpurple">
        <color rgba="0.42 0.33 0.63 1.0" />
      </material>
    </visual>
    <collision>
      <origin xyz="0 0 0.0" rpy="0 -1.5707963267948966 0" />
      <geometry>
        <cylinder length="0.46" radius="0.17" />
      </geometry>
    </collision>
    <inertial>
      <mass value="1.5e-06" />
      <inertia ixx="1.52488e-05" ixy="0.0" ixz="0.0" iyy="1.52488e-05" iyz="0.0" izz="1.52488e-05" />
    </inertial>
  </link>
  <joint name="act0Seg0_to_act0Seg1_ax0helper_shape" type="fixed">
    <parent link="act0Seg0" />
    <child link="act0Seg1helper_shape" />
    <origin xyz="0 0 0.05" rpy="0 0 0" />
    <axis xyz="1 0 0" />
  </joint>
  <link name="act0Seg2">
    <visual>
      <origin xyz="0.0 0.0 0.05" rpy="0.0 0.0 0.0" />
      <geometry>
        <box size="0.46 0.34 0.1" />
      </geometry>
      <material name="darkpurple">
        <color rgba="0.42 0.33 0.63 1.0" />
      </material>
    </visual>
    <collision>
      <origin xyz="0.0 0.0 0.05" rpy="0.0 0.0 0.0" />
      <geometry>
        <box size="0.46 0.34 0.1" />
      </geometry>
    </collision>
    <inertial>
      <mass value="0.0015" />
      <inertia ixx="0.0152488" ixy="0" ixz="0" iyy="0.0152488" iyz="0" izz="0.0152488" />
    </inertial>
  </link>
  <joint name="act0Seg1_to_act0Seg2_ax0" type="revolute">
    <parent link="act0Seg1" />
    <child link="act0Seg2" />
    <origin xyz="0.0 0.0 0.1" rpy="0.0 0.0 0.0" />
    <axis xyz="1 0 0" />
    <limit lower="-3.141592" upper="3.141592" effort="100" velocity="3" />
  </joint>
  <link name="act0Seg2helper_shape">
    <visual>
      <origin xyz="0 0 0.0" rpy="0 -1.5707963267948966 0" />
      <geometry>
        <cylinder length="0.46" radius="0.17" />
      </geometry>
      <material name="darkpurple">
        <color rgba="0.42 0.33 0.63 1.0" />
      </material>
    </visual>
    <collision>
      <origin xyz="0 0 0.0" rpy="0 -1.5707963267948966 0" />
      <geometry>
        <cylinder length="0.46" radius="0.17" />
      </geometry>
    </collision>
    <inertial>
      <mass value="1.5e-06" />
      <inertia ixx="1.52488e-05" ixy="0.0" ixz="0.0" iyy="1.52488e-05" iyz="0.0" izz="1.52488e-05" />
    </inertial>
  </link>
  <joint name="act0Seg1_to_act0Seg2_ax0helper_shape" type="fixed">
    <parent link="act0Seg1" />
    <child link="act0Seg2helper_shape" />
    <origin xyz="0.0 0.0 0.1" rpy="0.0 0.0 0.0" />
    <axis xyz="1 0 0" />
  </joint>
  <link name="act0Seg3">
    <visual>
      <origin xyz="0.0 0.0 0.05" rpy="0.0 0.0 0.0" />
      <geometry>
        <box size="0.46 0.34 0.1" />
      </geometry>
      <material name="darkpurple">
        <color rgba="0.42 0.33 0.63 1.0" />
      </material>
    </visual>
    <collision>
      <origin xyz="0.0 0.0 0.05" rpy="0.0 0.0 0.0" />
      <geometry>
        <box size="0.46 0.34 0.1" />
      </geometry>
    </collision>
    <inertial>
      <mass value="0.0015" />
      <inertia ixx="0.0152488" ixy="0" ixz="0" iyy="0.0152488" iyz="0" izz="0.0152488" />
    </inertial>
  </link>
  <joint name="act0Seg2_to_act0Seg3_ax0" type="revolute">
    <parent link="act0Seg2" />
    <child link="act0Seg3" />
    <origin xyz="0.0 0.0 0.1" rpy="0.0 0.0 0.0" />
    <axis xyz="1 0 0" />
    <limit lower="-3.141592" upper="3.141592" effort="100" velocity="3" />
  </joint>
  <link name="act0Seg3helper_shape">
    <visual>
      <origin xyz="0 0 0.0" rpy="0 -1.5707963267948966 0" />
      <geometry>
        <cylinder length="0.46" radius="0.17" />
      </geometry>
      <material name="darkpurple">
        <color rgba="0.42 0.33 0.63 1.0" />
      </material>
    </visual>
    <collision>
      <origin xyz="0 0 0.0" rpy="0 -1.5707963267948966 0" />
      <geometry>
        <cylinder length="0.46" radius="0.17" />
      </geometry>
    </collision>
    <inertial>
      <mass value="1.5e-06" />
      <inertia ixx="1.52488e-05" ixy="0.0" ixz="0.0" iyy="1.52488e-05" iyz="0.0" izz="1.52488e-05" />
    </inertial>
  </link>
  <joint name="act0Seg2_to_act0Seg3_ax0helper_shape" type="fixed">
    <parent link="act0Seg2" />
    <child link="act0Seg3helper_shape" />
    <origin xyz="0.0 0.0 0.1" rpy="0.0 0.0 0.0" />
    <axis xyz="1 0 0" />
  </joint>
  <link name="act0Seg4">
    <visual>
      <origin xyz="0.0 0.0 0.05" rpy="0.0 0.0 0.0" />
      <geometry>
        <box size="0.46 0.34 0.1" />
      </geometry>
      <material name="darkpurple">
        <color rgba="0.42 0.33 0.63 1.0" />
      </material>
    </visual>
    <collision>
      <origin xyz="0.0 0.0 0.05" rpy="0.0 0.0 0.0" />
      <geometry>
        <box size="0.46 0.34 0.1" />
      </geometry>
    </collision>
    <inertial>
      <mass value="0.0015" />
      <inertia ixx="0.0152488" ixy="0" ixz="0" iyy="0.0152488" iyz="0" izz="0.0152488" />
    </inertial>
  </link>
  <joint name="act0Seg3_to_act0Seg4_ax0" type="revolute">
    <parent link="act0Seg3" />
    <child link="act0Seg4" />
    <origin xyz="0.0 0.0 0.1" rpy="0.0 0.0 0.0" />
    <axis xyz="1 0 0" />
    <limit lower="-3.141592" upper="3.141592" effort="100" velocity="3" />
  </joint>
  <link name="act0Seg4helper_shape">
    <visual>
      <origin xyz="0 0 0.0" rpy="0 -1.5707963267948966 0" />
      <geometry>
        <cylinder length="0.46" radius="0.17" />
      </geometry>
      <material name="darkpurple">
        <color rgba="0.42 0.33 0.63 1.0" />
      </material>
    </visual>
    <collision>
      <origin xyz="0 0 0.0" rpy="0 -1.5707963267948966 0" />
      <geometry>
        <cylinder length="0.46" radius="0.17" />
      </geometry>
    </collision>
    <inertial>
      <mass value="1.5e-06" />
      <inertia ixx="1.52488e-05" ixy="0.0" ixz="0.0" iyy="1.52488e-05" iyz="0.0" izz="1.52488e-05" />
    </inertial>
  </link>
  <joint name="act0Seg3_to_act0Seg4_ax0helper_shape" type="fixed">
    <parent link="act0Seg3" />
    <child link="act0Seg4helper_shape" />
    <origin xyz="0.0 0.0 0.1" rpy="0.0 0.0 0.0" />
    <axis xyz="1 0 0" />
  </joint>
  <link name="act0Seg5">
    <visual>
      <origin xyz="0.0 0.0 0.05" rpy="0.0 0.0 0.0" />
      <geometry>
        <box size="0.46 0.34 0.1" />
      </geometry>
      <material name="darkpurple">
        <color rgba="0.42 0.33 0.63 1.0" />
      </material>
    </visual>
    <collision>
      <origin xyz="0.0 0.0 0.05" rpy="0.0 0.0 0.0" />
      <geometry>
        <box size="0.46 0.34 0.1" />
      </geometry>
    </collision>
    <inertial>
      <mass value="0.0015" />
      <inertia ixx="0.0152488" ixy="0" ixz="0" iyy="0.0152488" iyz="0" izz="0.0152488" />
    </inertial>
  </link>
  <joint name="act0Seg4_to_act0Seg5_ax0" type="revolute">
    <parent link="act0Seg4" />
    <child link="act0Seg5" />
    <origin xyz="0.0 0.0 0.1" rpy="0.0 0.0 0.0" />
    <axis xyz="1 0 0" />
    <limit lower="-3.141592" upper="3.141592" effort="100" velocity="3" />
  </joint>
  <link name="act0Seg5helper_shape">
    <visual>
      <origin xyz="0 0 0.0" rpy="0 -1.5707963267948966 0" />
      <geometry>
        <cylinder length="0.46" radius="0.17" />
      </geometry>
      <material name="darkpurple">
        <color rgba="0.42 0.33 0.63 1.0" />
      </material>
    </visual>
    <collision>
      <origin xyz="0 0 0.0" rpy="0 -1.5707963267948966 0" />
      <geometry>
        <cylinder length="0.46" radius="0.17" />
      </geometry>
    </collision>
    <inertial>
      <mass value="1.5e-06" />
      <inertia ixx="1.52488e-05" ixy="0.0" ixz="0.0" iyy="1.52488e-05" iyz="0.0" izz="1.52488e-05" />
    </inertial>
  </link>
  <joint name="act0Seg4_to_act0Seg5_ax0helper_shape" type="fixed">
    <parent link="act0Seg4" />
    <child link="act0Seg5helper_shape" />
    <origin xyz="0.0 0.0 0.1" rpy="0.0 0.0 0.0" />
    <axis xyz="1 0 0" />
  </joint>
  <link name="act0Seg6">
    <visual>
      <origin xyz="0.0 0.0 0.05" rpy="0.0 0.0 0.0" />
      <geometry>
        <box size="0.46 0.34 0.1" />
      </geometry>
      <material name="darkpurple">
        <color rgba="0.42 0.33 0.63 1.0" />
      </material>
    </visual>
    <collision>
      <origin xyz="0.0 0.0 0.05" rpy="0.0 0.0 0.0" />
      <geometry>
        <box size="0.46 0.34 0.1" />
      </geometry>
    </collision>
    <inertial>
      <mass value="0.0015" />
      <inertia ixx="0.0152488" ixy="0" ixz="0" iyy="0.0152488" iyz="0" izz="0.0152488" />
    </inertial>
  </link>
  <joint name="act0Seg5_to_act0Seg6_ax0" type="revolute">
    <parent link="act0Seg5" />
    <child link="act0Seg6" />
    <origin xyz="0.0 0.0 0.1" rpy="0.0 0.0 0.0" />
    <axis xyz="1 0 0" />
    <limit lower="-3.141592" upper="3.141592" effort="100" velocity="3" />
  </joint>
  <link name="act0Seg6helper_shape">
    <visual>
      <origin xyz="0 0 0.0" rpy="0 -1.5707963267948966 0" />
      <geometry>
        <cylinder length="0.46" radius="0.17" />
      </geometry>
      <material name="darkpurple">
        <color rgba="0.42 0.33 0.63 1.0" />
      </material>
    </visual>
    <collision>
      <origin xyz="0 0 0.0" rpy="0 -1.5707963267948966 0" />
      <geometry>
        <cylinder length="0.46" radius="0.17" />
      </geometry>
    </collision>
    <inertial>
      <mass value="1.5e-06" />
      <inertia ixx="1.52488e-05" ixy="0.0" ixz="0.0" iyy="1.52488e-05" iyz="0.0" izz="1.52488e-05" />
    </inertial>
  </link>
  <joint name="act0Seg5_to_act0Seg6_ax0helper_shape" type="fixed">
    <parent link="act0Seg5" />
    <child link="act0Seg6helper_shape" />
    <origin xyz="0.0 0.0 0.1" rpy="0.0 0.0 0.0" />
    <axis xyz="1 0 0" />
  </joint>
  <link name="act0Seg7">
    <visual>
      <origin xyz="0.0 0.0 0.05" rpy="0.0 0.0 0.0" />
      <geometry>
        <box size="0.46 0.34 0.1" />
      </geometry>
      <material name="darkpurple">
        <color rgba="0.42 0.33 0.63 1.0" />
      </material>
    </visual>
    <collision>
      <origin xyz="0.0 0.0 0.05" rpy="0.0 0.0 0.0" />
      <geometry>
        <box size="0.46 0.34 0.1" />
      </geometry>
    </collision>
    <inertial>
      <mass value="0.0015" />
      <inertia ixx="0.0152488" ixy="0" ixz="0" iyy="0.0152488" iyz="0" izz="0.0152488" />
    </inertial>
  </link>
  <joint name="act0Seg6_to_act0Seg7_ax0" type="revolute">
    <parent link="act0Seg6" />
    <child link="act0Seg7" />
    <origin xyz="0.0 0.0 0.1" rpy="0.0 0.0 0.0" />
    <axis xyz="1 0 0" />
    <limit lower="-3.141592" upper="3.141592" effort="100" velocity="3" />
  </joint>
  <link name="act0Seg7helper_shape">
    <visual>
      <origin xyz="0 0 0.0" rpy="0 -1.5707963267948966 0" />
      <geometry>
        <cylinder length="0.46" radius="0.17" />
      </geometry>
      <material name="darkpurple">
        <color rgba="0.42 0.33 0.63 1.0" />
      </material>
    </visual>
    <collision>
      <origin xyz="0 0 0.0" rpy="0 -1.5707963267948966 0" />
      <geometry>
        <cylinder length="0.46" radius="0.17" />
      </geometry>
    </collision>
    <inertial>
      <mass value="1.5e-06" />
      <inertia ixx="1.52488e-05" ixy="0.0" ixz="0.0" iyy="1.52488e-05" iyz="0.0" izz="1.52488e-05" />
    </inertial>
  </link>
  <joint name="act0Seg6_to_act0Seg7_ax0helper_shape" type="fixed">
    <parent link="act0Seg6" />
    <child link="act0Seg7helper_shape" />
    <origin xyz="0.0 0.0 0.1" rpy="0.0 0.0 0.0" />
    <axis xyz="1 0 0" />
  </joint>
  <link name="act0Seg8">
    <visual>
      <origin xyz="0.0 0.0 0.05" rpy="0.0 0.0 0.0" />
      <geometry>
        <box size="0.46 0.34 0.1" />
      </geometry>
      <material name="darkpurple">
        <color rgba="0.42 0.33 0.63 1.0" />
      </material>
    </visual>
    <collision>
      <origin xyz="0.0 0.0 0.05" rpy="0.0 0.0 0.0" />
      <geometry>
        <box size="0.46 0.34 0.1" />
      </geometry>
    </collision>
    <inertial>
      <mass value="0.0015" />
      <inertia ixx="0.0152488" ixy="0" ixz="0" iyy="0.0152488" iyz="0" izz="0.0152488" />
    </inertial>
  </link>
  <joint name="act0Seg7_to_act0Seg8_ax0" type="revolute">
    <parent link="act0Seg7" />
    <child link="act0Seg8" />
    <origin xyz="0.0 0.0 0.1" rpy="0.0 0.0 0.0" />
    <axis xyz="1 0 0" />
    <limit lower="-3.141592" upper="3.141592" effort="100" velocity="3" />
  </joint>
  <link name="act0Seg8helper_shape">
    <visual>
      <origin xyz="0 0 0.0" rpy="0 -1.5707963267948966 0" />
      <geometry>
        <cylinder length="0.46" radius="0.17" />
      </geometry>
      <material name="darkpurple">
        <color rgba="0.42 0.33 0.63 1.0" />
      </material>
    </visual>
    <collision>
      <origin xyz="0 0 0.0" rpy="0 -1.5707963267948966 0" />
      <geometry>
        <cylinder length="0.46" radius="0.17" />
      </geometry>
    </collision>
    <inertial>
      <mass value="1.5e-06" />
      <inertia ixx="1.52488e-05" ixy="0.0" ixz="0.0" iyy="1.52488e-05" iyz="0.0" izz="1.52488e-05" />
    </inertial>
  </link>
  <joint name="act0Seg7_to_act0Seg8_ax0helper_shape" type="fixed">
    <parent link="act0Seg7" />
    <child link="act0Seg8helper_shape" />
    <origin xyz="0.0 0.0 0.1" rpy="0.0 0.0 0.0" />
    <axis xyz="1 0 0" />
  </joint>
  <link name="act0Seg9">
    <visual>
      <origin xyz="0.0 0.0 0.05" rpy="0.0 0.0 0.0" />
      <geometry>
        <box size="0.46 0.34 0.1" />
      </geometry>
      <material name="darkpurple">
        <color rgba="0.42 0.33 0.63 1.0" />
      </material>
    </visual>
    <collision>
      <origin xyz="0.0 0.0 0.05" rpy="0.0 0.0 0.0" />
      <geometry>
        <box size="0.46 0.34 0.1" />
      </geometry>
    </collision>
    <inertial>
      <mass value="0.0015" />
      <inertia ixx="0.0152488" ixy="0" ixz="0" iyy="0.0152488" iyz="0" izz="0.0152488" />
    </inertial>
  </link>
  <joint name="act0Seg8_to_act0Seg9_ax0" type="revolute">
    <parent link="act0Seg8" />
    <child link="act0Seg9" />
    <origin xyz="0.0 0.0 0.1" rpy="0.0 0.0 0.0" />
    <axis xyz="1 0 0" />
    <limit lower="-3.141592" upper="3.141592" effort="100" velocity="3" />
  </joint>
  <link name="act0Seg9helper_shape">
    <visual>
      <origin xyz="0 0 0.0" rpy="0 -1.5707963267948966 0" />
      <geometry>
        <cylinder length="0.46" radius="0.17" />
      </geometry>
      <material name="darkpurple">
        <color rgba="0.42 0.33 0.63 1.0" />
      </material>
    </visual>
    <collision>
      <origin xyz="0 0 0.0" rpy="0 -1.5707963267948966 0" />
      <geometry>
        <cylinder length="0.46" radius="0.17" />
      </geometry>
    </collision>
    <inertial>
      <mass value="1.5e-06" />
      <inertia ixx="1.52488e-05" ixy="0.0" ixz="0.0" iyy="1.52488e-05" iyz="0.0" izz="1.52488e-05" />
    </inertial>
  </link>
  <joint name="act0Seg8_to_act0Seg9_ax0helper_shape" type="fixed">
    <parent link="act0Seg8" />
    <child link="act0Seg9helper_shape" />
    <origin xyz="0.0 0.0 0.1" rpy="0.0 0.0 0.0" />
    <axis xyz="1 0 0" />
  </joint>
  <link name="act0Seg10">
    <visual>
      <origin xyz="0.0 0.0 0.025" rpy="0.0 0.0 0.0" />
      <geometry>
        <box size="0.46 0.34 0.05" />
      </geometry>
      <material name="darkpurple">
        <color rgba="0.42 0.33 0.63 1.0" />
      </material>
    </visual>
    <collision>
      <origin xyz="0.0 0.0 0.025" rpy="0.0 0.0 0.0" />
      <geometry>
        <box size="0.46 0.34 0.05" />
      </geometry>
    </collision>
    <inertial>
      <mass value="0.0015" />
      <inertia ixx="0.0152488" ixy="0" ixz="0" iyy="0.0152488" iyz="0" izz="0.0152488" />
    </inertial>
  </link>
  <joint name="act0Seg9_to_act0Seg10_ax0" type="revolute">
    <parent link="act0Seg9" />
    <child link="act0Seg10" />
    <origin xyz="0.0 0.0 0.1" rpy="0.0 0.0 0.0" />
    <axis xyz="1 0 0" />
    <limit lower="-3.141592" upper="3.141592" effort="100" velocity="3" />
  </joint>
  <link name="act0Seg10helper_shape">
    <visual>
      <origin xyz="0 0 0.0" rpy="0 -1.5707963267948966 0" />
      <geometry>
        <cylinder length="0.46" radius="0.17" />
      </geometry>
      <material name="darkpurple">
        <color rgba="0.42 0.33 0.63 1.0" />
      </material>
    </visual>
    <collision>
      <origin xyz="0 0 0.0" rpy="0 -1.5707963267948966 0" />
      <geometry>
        <cylinder length="0.46" radius="0.17" />
      </geometry>
    </collision>
    <inertial>
      <mass value="1.5e-06" />
      <inertia ixx="1.52488e-05" ixy="0.0" ixz="0.0" iyy="1.52488e-05" iyz="0.0" izz="1.52488e-05" />
    </inertial>
  </link>
  <joint name="act0Seg9_to_act0Seg10_ax0helper_shape" type="fixed">
    <parent link="act0Seg9" />
    <child link="act0Seg10helper_shape" />
    <origin xyz="0.0 0.0 0.1" rpy="0.0 0.0 0.0" />
    <axis xyz="1 0 0" />
  </joint>
  <link name="act1Seg0">
    <visual>
      <origin xyz="0.0 0.0 0.025" rpy="0.0 0.0 0.0" />
      <geometry>
        <box size="0.46 0.34 0.05" />
      </geometry>
      <material name="lightpurple">
        <color rgba="0.644706 0.4894116 0.8282352000000001 1.0" />
      </material>
    </visual>
    <collision>
      <origin xyz="0.0 0.0 0.025" rpy="0.0 0.0 0.0" />
      <geometry>
        <box size="0.46 0.34 0.05" />
      </geometry>
    </collision>
    <inertial>
      <mass value="0.0015" />
      <inertia ixx="0.0152488" ixy="0" ixz="0" iyy="0.0152488" iyz="0" izz="0.0152488" />
    </inertial>
  </link>
  <joint name="act0Seg10_to_act1Seg0_ax0" type="fixed">
    <parent link="act0Seg10" />
    <child link="act1Seg0" />
    <origin xyz="0.0 0.0 0.05" rpy="0.0 0.0 0.0" />
    <axis xyz="1 0 0" />
    <limit lower="-3.141592" upper="3.141592" effort="100" velocity="3" />
  </joint>
  <link name="act1Seg1">
    <visual>
      <origin xyz="0.0 0.0 0.05" rpy="0.0 0.0 0.0" />
      <geometry>
        <box size="0.46 0.34 0.1" />
      </geometry>
      <material name="lightpurple">
        <color rgba="0.644706 0.4894116 0.8282352000000001 1.0" />
      </material>
    </visual>
    <collision>
      <origin xyz="0.0 0.0 0.05" rpy="0.0 0.0 0.0" />
      <geometry>
        <box size="0.46 0.34 0.1" />
      </geometry>
    </collision>
    <inertial>
      <mass value="0.0015" />
      <inertia ixx="0.0152488" ixy="0" ixz="0" iyy="0.0152488" iyz="0" izz="0.0152488" />
    </inertial>
  </link>
  <joint name="act1Seg0_to_act1Seg1_ax0" type="revolute">
    <parent link="act1Seg0" />
    <child link="act1Seg1" />
    <origin xyz="0.0 0.0 0.05" rpy="0.0 0.0 0.0" />
    <axis xyz="1 0 0" />
    <limit lower="-3.141592" upper="3.141592" effort="100" velocity="3" />
  </joint>
  <link name="act1Seg1helper_shape">
    <visual>
      <origin xyz="0 0 0.0" rpy="0 -1.5707963267948966 0" />
      <geometry>
        <cylinder length="0.46" radius="0.17" />
      </geometry>
      <material name="lightpurple">
        <color rgba="0.644706 0.4894116 0.8282352000000001 1.0" />
      </material>
    </visual>
    <collision>
      <origin xyz="0 0 0.0" rpy="0 -1.5707963267948966 0" />
      <geometry>
        <cylinder length="0.46" radius="0.17" />
      </geometry>
    </collision>
    <inertial>
      <mass value="1.5e-06" />
      <inertia ixx="1.52488e-05" ixy="0.0" ixz="0.0" iyy="1.52488e-05" iyz="0.0" izz="1.52488e-05" />
    </inertial>
  </link>
  <joint name="act1Seg0_to_act1Seg1_ax0helper_shape" type="fixed">
    <parent link="act1Seg0" />
    <child link="act1Seg1helper_shape" />
    <origin xyz="0.0 0.0 0.05" rpy="0.0 0.0 0.0" />
    <axis xyz="1 0 0" />
  </joint>
  <link name="act1Seg2">
    <visual>
      <origin xyz="0.0 0.0 0.05" rpy="0.0 0.0 0.0" />
      <geometry>
        <box size="0.46 0.34 0.1" />
      </geometry>
      <material name="lightpurple">
        <color rgba="0.644706 0.4894116 0.8282352000000001 1.0" />
      </material>
    </visual>
    <collision>
      <origin xyz="0.0 0.0 0.05" rpy="0.0 0.0 0.0" />
      <geometry>
        <box size="0.46 0.34 0.1" />
      </geometry>
    </collision>
    <inertial>
      <mass value="0.0015" />
      <inertia ixx="0.0152488" ixy="0" ixz="0" iyy="0.0152488" iyz="0" izz="0.0152488" />
    </inertial>
  </link>
  <joint name="act1Seg1_to_act1Seg2_ax0" type="revolute">
    <parent link="act1Seg1" />
    <child link="act1Seg2" />
    <origin xyz="0.0 0.0 0.1" rpy="0.0 0.0 0.0" />
    <axis xyz="1 0 0" />
    <limit lower="-3.141592" upper="3.141592" effort="100" velocity="3" />
  </joint>
  <link name="act1Seg2helper_shape">
    <visual>
      <origin xyz="0 0 0.0" rpy="0 -1.5707963267948966 0" />
      <geometry>
        <cylinder length="0.46" radius="0.17" />
      </geometry>
      <material name="lightpurple">
        <color rgba="0.644706 0.4894116 0.8282352000000001 1.0" />
      </material>
    </visual>
    <collision>
      <origin xyz="0 0 0.0" rpy="0 -1.5707963267948966 0" />
      <geometry>
        <cylinder length="0.46" radius="0.17" />
      </geometry>
    </collision>
    <inertial>
      <mass value="1.5e-06" />
      <inertia ixx="1.52488e-05" ixy="0.0" ixz="0.0" iyy="1.52488e-05" iyz="0.0" izz="1.52488e-05" />
    </inertial>
  </link>
  <joint name="act1Seg1_to_act1Seg2_ax0helper_shape" type="fixed">
    <parent link="act1Seg1" />
    <child link="act1Seg2helper_shape" />
    <origin xyz="0.0 0.0 0.1" rpy="0.0 0.0 0.0" />
    <axis xyz="1 0 0" />
  </joint>
  <link name="act1Seg3">
    <visual>
      <origin xyz="0.0 0.0 0.05" rpy="0.0 0.0 0.0" />
      <geometry>
        <box size="0.46 0.34 0.1" />
      </geometry>
      <material name="lightpurple">
        <color rgba="0.644706 0.4894116 0.8282352000000001 1.0" />
      </material>
    </visual>
    <collision>
      <origin xyz="0.0 0.0 0.05" rpy="0.0 0.0 0.0" />
      <geometry>
        <box size="0.46 0.34 0.1" />
      </geometry>
    </collision>
    <inertial>
      <mass value="0.0015" />
      <inertia ixx="0.0152488" ixy="0" ixz="0" iyy="0.0152488" iyz="0" izz="0.0152488" />
    </inertial>
  </link>
  <joint name="act1Seg2_to_act1Seg3_ax0" type="revolute">
    <parent link="act1Seg2" />
    <child link="act1Seg3" />
    <origin xyz="0.0 0.0 0.1" rpy="0.0 0.0 0.0" />
    <axis xyz="1 0 0" />
    <limit lower="-3.141592" upper="3.141592" effort="100" velocity="3" />
  </joint>
  <link name="act1Seg3helper_shape">
    <visual>
      <origin xyz="0 0 0.0" rpy="0 -1.5707963267948966 0" />
      <geometry>
        <cylinder length="0.46" radius="0.17" />
      </geometry>
      <material name="lightpurple">
        <color rgba="0.644706 0.4894116 0.8282352000000001 1.0" />
      </material>
    </visual>
    <collision>
      <origin xyz="0 0 0.0" rpy="0 -1.5707963267948966 0" />
      <geometry>
        <cylinder length="0.46" radius="0.17" />
      </geometry>
    </collision>
    <inertial>
      <mass value="1.5e-06" />
      <inertia ixx="1.52488e-05" ixy="0.0" ixz="0.0" iyy="1.52488e-05" iyz="0.0" izz="1.52488e-05" />
    </inertial>
  </link>
  <joint name="act1Seg2_to_act1Seg3_ax0helper_shape" type="fixed">
    <parent link="act1Seg2" />
    <child link="act1Seg3helper_shape" />
    <origin xyz="0.0 0.0 0.1" rpy="0.0 0.0 0.0" />
    <axis xyz="1 0 0" />
  </joint>
  <link name="act1Seg4">
    <visual>
      <origin xyz="0.0 0.0 0.05" rpy="0.0 0.0 0.0" />
      <geometry>
        <box size="0.46 0.34 0.1" />
      </geometry>
      <material name="lightpurple">
        <color rgba="0.644706 0.4894116 0.8282352000000001 1.0" />
      </material>
    </visual>
    <collision>
      <origin xyz="0.0 0.0 0.05" rpy="0.0 0.0 0.0" />
      <geometry>
        <box size="0.46 0.34 0.1" />
      </geometry>
    </collision>
    <inertial>
      <mass value="0.0015" />
      <inertia ixx="0.0152488" ixy="0" ixz="0" iyy="0.0152488" iyz="0" izz="0.0152488" />
    </inertial>
  </link>
  <joint name="act1Seg3_to_act1Seg4_ax0" type="revolute">
    <parent link="act1Seg3" />
    <child link="act1Seg4" />
    <origin xyz="0.0 0.0 0.1" rpy="0.0 0.0 0.0" />
    <axis xyz="1 0 0" />
    <limit lower="-3.141592" upper="3.141592" effort="100" velocity="3" />
  </joint>
  <link name="act1Seg4helper_shape">
    <visual>
      <origin xyz="0 0 0.0" rpy="0 -1.5707963267948966 0" />
      <geometry>
        <cylinder length="0.46" radius="0.17" />
      </geometry>
      <material name="lightpurple">
        <color rgba="0.644706 0.4894116 0.8282352000000001 1.0" />
      </material>
    </visual>
    <collision>
      <origin xyz="0 0 0.0" rpy="0 -1.5707963267948966 0" />
      <geometry>
        <cylinder length="0.46" radius="0.17" />
      </geometry>
    </collision>
    <inertial>
      <mass value="1.5e-06" />
      <inertia ixx="1.52488e-05" ixy="0.0" ixz="0.0" iyy="1.52488e-05" iyz="0.0" izz="1.52488e-05" />
    </inertial>
  </link>
  <joint name="act1Seg3_to_act1Seg4_ax0helper_shape" type="fixed">
    <parent link="act1Seg3" />
    <child link="act1Seg4helper_shape" />
    <origin xyz="0.0 0.0 0.1" rpy="0.0 0.0 0.0" />
    <axis xyz="1 0 0" />
  </joint>
  <link name="act1Seg5">
    <visual>
      <origin xyz="0.0 0.0 0.05" rpy="0.0 0.0 0.0" />
      <geometry>
        <box size="0.46 0.34 0.1" />
      </geometry>
      <material name="lightpurple">
        <color rgba="0.644706 0.4894116 0.8282352000000001 1.0" />
      </material>
    </visual>
    <collision>
      <origin xyz="0.0 0.0 0.05" rpy="0.0 0.0 0.0" />
      <geometry>
        <box size="0.46 0.34 0.1" />
      </geometry>
    </collision>
    <inertial>
      <mass value="0.0015" />
      <inertia ixx="0.0152488" ixy="0" ixz="0" iyy="0.0152488" iyz="0" izz="0.0152488" />
    </inertial>
  </link>
  <joint name="act1Seg4_to_act1Seg5_ax0" type="revolute">
    <parent link="act1Seg4" />
    <child link="act1Seg5" />
    <origin xyz="0.0 0.0 0.1" rpy="0.0 0.0 0.0" />
    <axis xyz="1 0 0" />
    <limit lower="-3.141592" upper="3.141592" effort="100" velocity="3" />
  </joint>
  <link name="act1Seg5helper_shape">
    <visual>
      <origin xyz="0 0 0.0" rpy="0 -1.5707963267948966 0" />
      <geometry>
        <cylinder length="0.46" radius="0.17" />
      </geometry>
      <material name="lightpurple">
        <color rgba="0.644706 0.4894116 0.8282352000000001 1.0" />
      </material>
    </visual>
    <collision>
      <origin xyz="0 0 0.0" rpy="0 -1.5707963267948966 0" />
      <geometry>
        <cylinder length="0.46" radius="0.17" />
      </geometry>
    </collision>
    <inertial>
      <mass value="1.5e-06" />
      <inertia ixx="1.52488e-05" ixy="0.0" ixz="0.0" iyy="1.52488e-05" iyz="0.0" izz="1.52488e-05" />
    </inertial>
  </link>
  <joint name="act1Seg4_to_act1Seg5_ax0helper_shape" type="fixed">
    <parent link="act1Seg4" />
    <child link="act1Seg5helper_shape" />
    <origin xyz="0.0 0.0 0.1" rpy="0.0 0.0 0.0" />
    <axis xyz="1 0 0" />
  </joint>
  <link name="act1Seg6">
    <visual>
      <origin xyz="0.0 0.0 0.05" rpy="0.0 0.0 0.0" />
      <geometry>
        <box size="0.46 0.34 0.1" />
      </geometry>
      <material name="lightpurple">
        <color rgba="0.644706 0.4894116 0.8282352000000001 1.0" />
      </material>
    </visual>
    <collision>
      <origin xyz="0.0 0.0 0.05" rpy="0.0 0.0 0.0" />
      <geometry>
        <box size="0.46 0.34 0.1" />
      </geometry>
    </collision>
    <inertial>
      <mass value="0.0015" />
      <inertia ixx="0.0152488" ixy="0" ixz="0" iyy="0.0152488" iyz="0" izz="0.0152488" />
    </inertial>
  </link>
  <joint name="act1Seg5_to_act1Seg6_ax0" type="revolute">
    <parent link="act1Seg5" />
    <child link="act1Seg6" />
    <origin xyz="0.0 0.0 0.1" rpy="0.0 0.0 0.0" />
    <axis xyz="1 0 0" />
    <limit lower="-3.141592" upper="3.141592" effort="100" velocity="3" />
  </joint>
  <link name="act1Seg6helper_shape">
    <visual>
      <origin xyz="0 0 0.0" rpy="0 -1.5707963267948966 0" />
      <geometry>
        <cylinder length="0.46" radius="0.17" />
      </geometry>
      <material name="lightpurple">
        <color rgba="0.644706 0.4894116 0.8282352000000001 1.0" />
      </material>
    </visual>
    <collision>
      <origin xyz="0 0 0.0" rpy="0 -1.5707963267948966 0" />
      <geometry>
        <cylinder length="0.46" radius="0.17" />
      </geometry>
    </collision>
    <inertial>
      <mass value="1.5e-06" />
      <inertia ixx="1.52488e-05" ixy="0.0" ixz="0.0" iyy="1.52488e-05" iyz="0.0" izz="1.52488e-05" />
    </inertial>
  </link>
  <joint name="act1Seg5_to_act1Seg6_ax0helper_shape" type="fixed">
    <parent link="act1Seg5" />
    <child link="act1Seg6helper_shape" />
    <origin xyz="0.0 0.0 0.1" rpy="0.0 0.0 0.0" />
    <axis xyz="1 0 0" />
  </joint>
  <link name="act1Seg7">
    <visual>
      <origin xyz="0.0 0.0 0.05" rpy="0.0 0.0 0.0" />
      <geometry>
        <box size="0.46 0.34 0.1" />
      </geometry>
      <material name="lightpurple">
        <color rgba="0.644706 0.4894116 0.8282352000000001 1.0" />
      </material>
    </visual>
    <collision>
      <origin xyz="0.0 0.0 0.05" rpy="0.0 0.0 0.0" />
      <geometry>
        <box size="0.46 0.34 0.1" />
      </geometry>
    </collision>
    <inertial>
      <mass value="0.0015" />
      <inertia ixx="0.0152488" ixy="0" ixz="0" iyy="0.0152488" iyz="0" izz="0.0152488" />
    </inertial>
  </link>
  <joint name="act1Seg6_to_act1Seg7_ax0" type="revolute">
    <parent link="act1Seg6" />
    <child link="act1Seg7" />
    <origin xyz="0.0 0.0 0.1" rpy="0.0 0.0 0.0" />
    <axis xyz="1 0 0" />
    <limit lower="-3.141592" upper="3.141592" effort="100" velocity="3" />
  </joint>
  <link name="act1Seg7helper_shape">
    <visual>
      <origin xyz="0 0 0.0" rpy="0 -1.5707963267948966 0" />
      <geometry>
        <cylinder length="0.46" radius="0.17" />
      </geometry>
      <material name="lightpurple">
        <color rgba="0.644706 0.4894116 0.8282352000000001 1.0" />
      </material>
    </visual>
    <collision>
      <origin xyz="0 0 0.0" rpy="0 -1.5707963267948966 0" />
      <geometry>
        <cylinder length="0.46" radius="0.17" />
      </geometry>
    </collision>
    <inertial>
      <mass value="1.5e-06" />
      <inertia ixx="1.52488e-05" ixy="0.0" ixz="0.0" iyy="1.52488e-05" iyz="0.0" izz="1.52488e-05" />
    </inertial>
  </link>
  <joint name="act1Seg6_to_act1Seg7_ax0helper_shape" type="fixed">
    <parent link="act1Seg6" />
    <child link="act1Seg7helper_shape" />
    <origin xyz="0.0 0.0 0.1" rpy="0.0 0.0 0.0" />
    <axis xyz="1 0 0" />
  </joint>
  <link name="act1Seg8">
    <visual>
      <origin xyz="0.0 0.0 0.05" rpy="0.0 0.0 0.0" />
      <geometry>
        <box size="0.46 0.34 0.1" />
      </geometry>
      <material name="lightpurple">
        <color rgba="0.644706 0.4894116 0.8282352000000001 1.0" />
      </material>
    </visual>
    <collision>
      <origin xyz="0.0 0.0 0.05" rpy="0.0 0.0 0.0" />
      <geometry>
        <box size="0.46 0.34 0.1" />
      </geometry>
    </collision>
    <inertial>
      <mass value="0.0015" />
      <inertia ixx="0.0152488" ixy="0" ixz="0" iyy="0.0152488" iyz="0" izz="0.0152488" />
    </inertial>
  </link>
  <joint name="act1Seg7_to_act1Seg8_ax0" type="revolute">
    <parent link="act1Seg7" />
    <child link="act1Seg8" />
    <origin xyz="0.0 0.0 0.1" rpy="0.0 0.0 0.0" />
    <axis xyz="1 0 0" />
    <limit lower="-3.141592" upper="3.141592" effort="100" velocity="3" />
  </joint>
  <link name="act1Seg8helper_shape">
    <visual>
      <origin xyz="0 0 0.0" rpy="0 -1.5707963267948966 0" />
      <geometry>
        <cylinder length="0.46" radius="0.17" />
      </geometry>
      <material name="lightpurple">
        <color rgba="0.644706 0.4894116 0.8282352000000001 1.0" />
      </material>
    </visual>
    <collision>
      <origin xyz="0 0 0.0" rpy="0 -1.5707963267948966 0" />
      <geometry>
        <cylinder length="0.46" radius="0.17" />
      </geometry>
    </collision>
    <inertial>
      <mass value="1.5e-06" />
      <inertia ixx="1.52488e-05" ixy="0.0" ixz="0.0" iyy="1.52488e-05" iyz="0.0" izz="1.52488e-05" />
    </inertial>
  </link>
  <joint name="act1Seg7_to_act1Seg8_ax0helper_shape" type="fixed">
    <parent link="act1Seg7" />
    <child link="act1Seg8helper_shape" />
    <origin xyz="0.0 0.0 0.1" rpy="0.0 0.0 0.0" />
    <axis xyz="1 0 0" />
  </joint>
  <link name="act1Seg9">
    <visual>
      <origin xyz="0.0 0.0 0.05" rpy="0.0 0.0 0.0" />
      <geometry>
        <box size="0.46 0.34 0.1" />
      </geometry>
      <material name="lightpurple">
        <color rgba="0.644706 0.4894116 0.8282352000000001 1.0" />
      </material>
    </visual>
    <collision>
      <origin xyz="0.0 0.0 0.05" rpy="0.0 0.0 0.0" />
      <geometry>
        <box size="0.46 0.34 0.1" />
      </geometry>
    </collision>
    <inertial>
      <mass value="0.0015" />
      <inertia ixx="0.0152488" ixy="0" ixz="0" iyy="0.0152488" iyz="0" izz="0.0152488" />
    </inertial>
  </link>
  <joint name="act1Seg8_to_act1Seg9_ax0" type="revolute">
    <parent link="act1Seg8" />
    <child link="act1Seg9" />
    <origin xyz="0.0 0.0 0.1" rpy="0.0 0.0 0.0" />
    <axis xyz="1 0 0" />
    <limit lower="-3.141592" upper="3.141592" effort="100" velocity="3" />
  </joint>
  <link name="act1Seg9helper_shape">
    <visual>
      <origin xyz="0 0 0.0" rpy="0 -1.5707963267948966 0" />
      <geometry>
        <cylinder length="0.46" radius="0.17" />
      </geometry>
      <material name="lightpurple">
        <color rgba="0.644706 0.4894116 0.8282352000000001 1.0" />
      </material>
    </visual>
    <collision>
      <origin xyz="0 0 0.0" rpy="0 -1.5707963267948966 0" />
      <geometry>
        <cylinder length="0.46" radius="0.17" />
      </geometry>
    </collision>
    <inertial>
      <mass value="1.5e-06" />
      <inertia ixx="1.52488e-05" ixy="0.0" ixz="0.0" iyy="1.52488e-05" iyz="0.0" izz="1.52488e-05" />
    </inertial>
  </link>
  <joint name="act1Seg8_to_act1Seg9_ax0helper_shape" type="fixed">
    <parent link="act1Seg8" />
    <child link="act1Seg9helper_shape" />
    <origin xyz="0.0 0.0 0.1" rpy="0.0 0.0 0.0" />
    <axis xyz="1 0 0" />
  </joint>
  <link name="act1Seg10">
    <visual>
      <origin xyz="0.0 0.0 0.025" rpy="0.0 0.0 0.0" />
      <geometry>
        <box size="0.46 0.34 0.05" />
      </geometry>
      <material name="lightpurple">
        <color rgba="0.644706 0.4894116 0.8282352000000001 1.0" />
      </material>
    </visual>
    <collision>
      <origin xyz="0.0 0.0 0.025" rpy="0.0 0.0 0.0" />
      <geometry>
        <box size="0.46 0.34 0.05" />
      </geometry>
    </collision>
    <inertial>
      <mass value="0.0015" />
      <inertia ixx="0.0152488" ixy="0" ixz="0" iyy="0.0152488" iyz="0" izz="0.0152488" />
    </inertial>
  </link>
  <joint name="act1Seg9_to_act1Seg10_ax0" type="revolute">
    <parent link="act1Seg9" />
    <child link="act1Seg10" />
    <origin xyz="0.0 0.0 0.1" rpy="0.0 0.0 0.0" />
    <axis xyz="1 0 0" />
    <limit lower="-3.141592" upper="3.141592" effort="100" velocity="3" />
  </joint>
  <link name="act1Seg10helper_shape">
    <visual>
      <origin xyz="0 0 0.0" rpy="0 -1.5707963267948966 0" />
      <geometry>
        <cylinder length="0.46" radius="0.17" />
      </geometry>
      <material name="lightpurple">
        <color rgba="0.644706 0.4894116 0.8282352000000001 1.0" />
      </material>
    </visual>
    <collision>
      <origin xyz="0 0 0.0" rpy="0 -1.5707963267948966 0" />
      <geometry>
        <cylinder length="0.46" radius="0.17" />
      </geometry>
    </collision>
    <inertial>
      <mass value="1.5e-06" />
      <inertia ixx="1.52488e-05" ixy="0.0" ixz="0.0" iyy="1.52488e-05" iyz="0.0" izz="1.52488e-05" />
    </inertial>
  </link>
  <joint name="act1Seg9_to_act1Seg10_ax0helper_shape" type="fixed">
    <parent link="act1Seg9" />
    <child link="act1Seg10helper_shape" />
    <origin xyz="0.0 0.0 0.1" rpy="0.0 0.0 0.0" />
    <axis xyz="1 0 0" />
  </joint>
  <link name="tip_link">
    <visual>
      <origin xyz="0 0 0.1" rpy="0 0 0" />
      <geometry>
        <box size="0.46 0.34 0.2" />
      </geometry>
      <material name="lightpurple">
        <color rgba="0.644706 0.4894116 0.8282352000000001 1.0" />
      </material>
    </visual>
    <collision>
      <origin xyz="0 0 0.1" rpy="0 0 0" />
      <geometry>
        <box size="0.46 0.34 0.2" />
      </geometry>
    </collision>
    <inertial>
      <mass value="0.0015" />
      <inertia ixx="0.0152488" ixy="0" ixz="0" iyy="0.0152488" iyz="0" izz="0.0152488" />
    </inertial>
  </link>
  <joint name="act1Seg10_to_tip_link" type="fixed">
    <parent link="act1Seg10" />
    <child link="tip_link" />
    <origin xyz="0.0 0.0 0.05" rpy="0.0 0.0 0.0" />
    <axis xyz="1 0 0" />
  </joint>
</robot>
